<mujoco model="demo">
    <actuator>
        <!-- <motor joint="root"         name="torque_body"/>
        <motor joint="root_y"       name="torque_body_y"/>
        <motor joint="root_z"       name="torque_body_z"/>
        <motor joint="root_r"       name="torque_body_r"/>
        <motor joint="root_p"       name="torque_body_p"/>
        <motor joint="root_yw"      name="torque_body_yw"/> -->

        <motor joint="joint_neck"               name="torque_neck"          ctrllimited="true"     ctrlrange="-80.0 80.0"/>
        <motor joint="joint_neck_y"             name="torque_neck_y"        ctrllimited="true"     ctrlrange="-80.0 80.0"/>
        <motor joint="joint_neck_z"             name="torque_neck_z"        ctrllimited="true"     ctrlrange="-80.0 80.0"/>
        <motor joint="joint_neck_r"             name="torque_neck_r"        ctrllimited="true"     ctrlrange="-80.0 80.0"/>
        <motor joint="joint_neck_p"             name="torque_neck_p"        ctrllimited="true"     ctrlrange="-80.0 80.0"/>
        <motor joint="joint_neck_yw"            name="torque_neck_yw"       ctrllimited="true"     ctrlrange="-80.0 80.0"/>

        <motor joint="joint_right_hand"         name="torque_right_hand"    ctrllimited="true"     ctrlrange="-80.0 80.0"/>
        <motor joint="joint_right_hand_y"       name="torque_right_hand_y"  ctrllimited="true"     ctrlrange="-80.0 80.0"/>
        <motor joint="joint_right_hand_z"       name="torque_right_hand_z"  ctrllimited="true"     ctrlrange="-80.0 80.0"/>
        <motor joint="joint_right_hand_r"       name="torque_right_hand_r"  ctrllimited="true"     ctrlrange="-80.0 80.0"/>
        <motor joint="joint_right_hand_p"       name="torque_right_hand_p"  ctrllimited="true"     ctrlrange="-80.0 80.0"/>
        <motor joint="joint_right_hand_yw"      name="torque_right_hand_yw" ctrllimited="true"     ctrlrange="-80.0 80.0"/>

        <motor joint="joint_left_hand"         name="torque_left_hand"      ctrllimited="true"     ctrlrange="-80.0 80.0"/>
        <motor joint="joint_left_hand_y"       name="torque_left_hand_y"    ctrllimited="true"     ctrlrange="-80.0 80.0"/>
        <motor joint="joint_left_hand_z"       name="torque_left_hand_z"    ctrllimited="true"     ctrlrange="-80.0 80.0"/>
        <motor joint="joint_left_hand_r"       name="torque_left_hand_r"    ctrllimited="true"     ctrlrange="-80.0 80.0"/>
        <motor joint="joint_left_hand_p"       name="torque_left_hand_p"    ctrllimited="true"     ctrlrange="-80.0 80.0"/>
        <motor joint="joint_left_hand_yw"      name="torque_left_hand_yw"   ctrllimited="true"     ctrlrange="-80.0 80.0"/>

    </actuator>

    <asset>
        <mesh file="meshes/hand.stl" name="right_hand_mesh" scale="0.002 0.002 0.002"/>
        <mesh file="meshes/hand.stl" name="left_hand_mesh" scale="0.002 -0.002 0.002"/>
        <material name="MatMetal" specular="1" shininess="0.3" rgba="0.9 0.9 0.9 1" />
    </asset>

    <worldbody>
        <body name="floating_base" pos="0 0 0.6">

        <body>
            <!-- <joint name="root" axis="1 0 0"
                type="slide" limited="false" 
                armature="0" stiffness="0" damping="0.0" frictionloss="0.99" 
                /> -->
            <inertial pos="0 0 0" mass="1.0e-6" diaginertia="1.0e-9 1.0e-9 1.0e-9"/>
        <body>
            <!-- <joint name="root_y" axis="0 1 0"
                type="slide" limited="false" 
                armature="0" stiffness="0" damping="0.0" frictionloss="0.99" 
                /> -->
            <inertial pos="0 0 0" mass="1.0e-6" diaginertia="1.0e-9 1.0e-9 1.0e-9"/>
        <body>
            <!-- <joint name="root_z" axis="0 0 1"
                type="slide" limited="false" 
                armature="0" stiffness="0" damping="0.0" frictionloss="0.99" 
                /> -->
            <inertial pos="0 0 0" mass="1.0e-6" diaginertia="1.0e-9 1.0e-9 1.0e-9"/>
        <body>
            <!-- <joint name="root_r" axis="1 0 0"
                type="hinge" limited="false" 
                armature="0" stiffness="0" damping="0.0" frictionloss="0.99" 
                /> -->
            <inertial pos="0 0 0" mass="1.0e-6" diaginertia="1.0e-9 1.0e-9 1.0e-9"/>
        <body>
            <!-- <joint name="root_p" axis="0 1 0"
                type="hinge" limited="false" 
                armature="0" stiffness="0" damping="0.0" frictionloss="0.99" 
                /> -->
            <inertial pos="0 0 0" mass="1.0e-6" diaginertia="1.0e-9 1.0e-9 1.0e-9"/>
        <body name="base" pos="0 0 0">
            <inertial pos="0 0 0" mass="1.0e-1" diaginertia="1.0e-3 1.0e-3 1.0e-3"/>
            <!-- <joint name="root_yw" axis="0 0 1"
                type="hinge" limited="false" 
                armature="0" stiffness="0" damping="0.0" frictionloss="0.99" 
                /> -->
            <!-- <joint armature="0" damping="0" limited="false" name="root_quat" stiffness="0" type="ball"/> -->

            <geom type="sphere" size="0.1" pos="0 0 0.1"
                rgba="1.0 0.2 0.2 1"
                contype="0" conaffinity="0" group="1" 
                />
            <geom type="sphere" size="0.075" pos="0 0 -0.1"
                rgba="1.0 0.2 0.2 1"
                contype="0" conaffinity="0" group="1" 
                />

            <body name="neck" pos="0 0 0.2">
                <joint name="joint_neck" axis="1 0 0" 
                    type="slide" limited="false" 
                    armature="0" stiffness="0" damping="0.99" frictionloss="0.99" 
                    />
                <inertial pos="0 0 0" mass="1.0e-6" diaginertia="1.0e-9 1.0e-9 1.0e-9"/>
            <body>
                <joint name="joint_neck_y" axis="0 1 0"
                    type="slide" limited="false" 
                    armature="0" stiffness="0" damping="0.99" frictionloss="0.99" 
                    />
                <inertial pos="0 0 0" mass="1.0e-6" diaginertia="1.0e-9 1.0e-9 1.0e-9"/>
            <body>
                <joint name="joint_neck_z" axis="0 0 1"
                    type="slide" limited="false" 
                    armature="0" stiffness="0" damping="0.99" frictionloss="0.99" 
                    />
                <inertial pos="0 0 0" mass="1.0e-6" diaginertia="1.0e-9 1.0e-9 1.0e-9"/>
            <body>
                <joint name="joint_neck_r" axis="1 0 0"
                    type="hinge" limited="false" 
                    armature="0" stiffness="0" damping="0.99" frictionloss="0.99" 
                    />
                <inertial pos="0 0 0" mass="1.0e-6" diaginertia="1.0e-9 1.0e-9 1.0e-9"/>
            <body>
                <joint name="joint_neck_p" axis="0 1 0"
                    type="hinge" limited="false" 
                    armature="0" stiffness="0" damping="0.99" frictionloss="0.99" 
                    />
                <inertial pos="0 0 0" mass="1.0e-6" diaginertia="1.0e-9 1.0e-9 1.0e-9"/>
            <body name="head" pos="0 0 0">
                <inertial pos="0 0 0" mass="1.0e-0" diaginertia="1.0e-4 1.0e-4 1.0e-4"/>
                <joint name="joint_neck_yw" axis="0 0 1"
                    type="hinge" limited="false" 
                    armature="0" stiffness="0" damping="0.99" frictionloss="0.99" 
                    />
                <geom type="sphere" size="0.075" pos="0 0 0.15"
                    rgba="1.0 0.2 0.2 1"
                    contype="0" conaffinity="0" group="1" 
                    />
                <camera mode="fixed" name="egoview" pos="0.075 0.0 0.15" quat="0.5 -0.5 -0.5 0.5" />

            </body>
            </body>
            </body>
            </body>
            </body>
            </body>

            <body pos="0 0.2 0.2">
                <joint name="joint_left_hand" axis="1 0 0"
                    type="slide" limited="false" 
                    armature="0" stiffness="0" damping="0.99" frictionloss="0.99" 
                    />
                <inertial pos="0 0 0" mass="1.0e-6" diaginertia="1.0e-9 1.0e-9 1.0e-9"/>
            <body>
                <joint name="joint_left_hand_y" axis="0 1 0"
                    type="slide" limited="false" 
                    armature="0" stiffness="0" damping="0.99" frictionloss="0.99" 
                    />
                <inertial pos="0 0 0" mass="1.0e-6" diaginertia="1.0e-9 1.0e-9 1.0e-9"/>
            <body>
                <joint name="joint_left_hand_z" axis="0 0 1"
                    type="slide" limited="false" 
                    armature="0" stiffness="0" damping="0.99" frictionloss="0.99" 
                    />
                <inertial pos="0 0 0" mass="1.0e-6" diaginertia="1.0e-9 1.0e-9 1.0e-9"/>
            <body>
                <joint name="joint_left_hand_r" axis="1 0 0"
                    type="hinge" limited="false" 
                    armature="0" stiffness="0" damping="0.99" frictionloss="0.99" 
                    />
                <inertial pos="0 0 0" mass="1.0e-6" diaginertia="1.0e-9 1.0e-9 1.0e-9"/>
            <body>
                <joint name="joint_left_hand_p" axis="0 1 0"
                    type="hinge" limited="false" 
                    armature="0" stiffness="0" damping="0.99" frictionloss="0.99" 
                    />
                <inertial pos="0 0 0" mass="1.0e-6" diaginertia="1.0e-9 1.0e-9 1.0e-9"/>
            <body name="left_arm" pos="0 0 0">
                <inertial pos="0 0 0" mass="1.0e-0" diaginertia="1.0e-4 1.0e-4 1.0e-4"/>
                <geom name='geom_left_hand_visual' 
                    pos="-0.03 0.0 0.03" type="mesh" mesh="left_hand_mesh" quat=" 0 -0.5 0 0.80"
                    group="1" contype="0" conaffinity="0"
                    rgba="1.0 0.2 0.2 1"
                    />
                <joint name="joint_left_hand_yw" axis="0 0 1"
                    type="hinge" limited="false" 
                    armature="0" stiffness="0" damping="0.99" frictionloss="0.99" 
                    />
                <body name="left_eef_point" pos="0 0 0">
                    <body name="left_gripper_mount" pos="0 0 0" quat="0.5 0.5 0.5 0.5">
                        <camera mode="fixed" name="stereo_l_left_hand" pos="0.05 0.1 -0.1" quat="0 1 0 0" fovy="75"/>
                        <camera mode="fixed" name="stereo_r_left_hand" pos="-0.05 0.1 -0.1" quat="0 1 0 0" fovy="75"/>
                    </body>
                </body>
                <body name="left_tool_point" pos="0 0 0">
                    <body name="left_tool_mount" pos="0.0 0.0 0.0" quat="0.5 0.5 0.5 0.5"/>
                </body>

            </body>
            </body>
            </body>
            </body>
            </body>
            </body>


            <body pos="0 -0.2 0.2">
                <joint name="joint_right_hand" axis="1 0 0"
                    type="slide" limited="false" 
                    armature="0" stiffness="0" damping="0.99" frictionloss="0.99" 
                    />
                <inertial pos="0 0 0" mass="1.0e-6" diaginertia="1.0e-9 1.0e-9 1.0e-9"/>
            <body>
                <joint name="joint_right_hand_y" axis="0 1 0"
                    type="slide" limited="false" 
                    armature="0" stiffness="0" damping="0.99" frictionloss="0.99" 
                    />
                <inertial pos="0 0 0" mass="1.0e-6" diaginertia="1.0e-9 1.0e-9 1.0e-9"/>
            <body>
                <joint name="joint_right_hand_z" axis="0 0 1"
                    type="slide" limited="false" 
                    armature="0" stiffness="0" damping="0.99" frictionloss="0.99" 
                    />
                <inertial pos="0 0 0" mass="1.0e-6" diaginertia="1.0e-9 1.0e-9 1.0e-9"/>
            <body>
                <joint name="joint_right_hand_r" axis="1 0 0"
                    type="hinge" limited="false" 
                    armature="0" stiffness="0" damping="0.99" frictionloss="0.99" 
                    />
                <inertial pos="0 0 0" mass="1.0e-6" diaginertia="1.0e-9 1.0e-9 1.0e-9"/>
            <body>
                <joint name="joint_right_hand_p" axis="0 1 0"
                    type="hinge" limited="false" 
                    armature="0" stiffness="0" damping="0.99" frictionloss="0.99" 
                    />
                <inertial pos="0 0 0" mass="1.0e-6" diaginertia="1.0e-9 1.0e-9 1.0e-9"/>
            <body name="right_arm" pos="0 0 0">
                <inertial pos="0 0 0" mass="1.0e-0" diaginertia="1.0e-4 1.0e-4 1.0e-4"/>
                <geom name='geom_right_hand_visual' 
                    pos="-0.03 0.0 0.03" type="mesh" mesh="right_hand_mesh" quat=" 0 -0.5 0 0.80"
                    group="1" contype="0" conaffinity="0"
                    rgba="1.0 0.2 0.2 1"
                    />
                <joint name="joint_right_hand_yw" axis="0 0 1"
                    type="hinge" limited="false" 
                    armature="0" stiffness="0" damping="0.99" frictionloss="0.99" 
                    />
                <body name="right_eef_point" pos="0 0 0">
                    <body name="right_gripper_mount" pos="0 0 0" quat="0.5 0.5 0.5 0.5">
                        <camera mode="fixed" name="stereo_l_right_hand" pos="0.05 0.1 0.0" quat="0 1 0 0" fovy="120"/>
                        <camera mode="fixed" name="stereo_r_right_hand" pos="-0.05 0.1 0.0" quat="0 1 0 0" fovy="120"/>
                    </body>
                </body>
                <body name="right_tool_point" pos="0 0 0">
                    <body name="right_tool_mount" pos="0.0 0.0 0.0" quat="0.5 0.5 0.5 0.5"/>
                </body>
            </body>
            </body>
            </body>
            </body>
            </body>
            </body>

        </body>
        </body>
        </body>
        </body>
        </body>
        </body>

        </body>
    </worldbody>
</mujoco>
