<mujoco model="spot">

    <actuator>
    
        <motor name="torque_body"       ctrllimited="true" ctrlrange="-2500 2500"  joint="root"   />
        <motor name="torque_body_y"     ctrllimited="true" ctrlrange="-2500 2500"  joint="root_y" />
        <motor name="torque_body_z"     ctrllimited="true" ctrlrange="-2500 2500"  joint="root_z" />
        <motor name="torque_body_r"     ctrllimited="true" ctrlrange="-2500 2500"  joint="root_r" />
        <motor name="torque_body_p"     ctrllimited="true" ctrlrange="-2500 2500"  joint="root_p" />
        <motor name="torque_body_yw"    ctrllimited="true" ctrlrange="-2500 2500"  joint="root_yw"/>

        <motor name="torque_quad_fr_0"  ctrllimited="true" ctrlrange="-500 500"   joint="joint_quad_fr_0" />
        <motor name="torque_quad_fr_1"  ctrllimited="true" ctrlrange="-500 500"   joint="joint_quad_fr_1" />
        <motor name="torque_quad_fr_2"  ctrllimited="true" ctrlrange="-500 500"   joint="joint_quad_fr_2" />
        
        <motor name="torque_quad_fl_0"  ctrllimited="true" ctrlrange="-500 500"   joint="joint_quad_fl_0" />
        <motor name="torque_quad_fl_1"  ctrllimited="true" ctrlrange="-500 500"   joint="joint_quad_fl_1" />
        <motor name="torque_quad_fl_2"  ctrllimited="true" ctrlrange="-500 500"   joint="joint_quad_fl_2" />
        
        <motor name="torque_quad_rr_0"  ctrllimited="true" ctrlrange="-500 500"   joint="joint_quad_rr_0" />
        <motor name="torque_quad_rr_1"  ctrllimited="true" ctrlrange="-500 500"   joint="joint_quad_rr_1" />
        <motor name="torque_quad_rr_2"  ctrllimited="true" ctrlrange="-500 500"   joint="joint_quad_rr_2" />
         
        <motor name="torque_quad_rl_0"  ctrllimited="true" ctrlrange="-500 500"   joint="joint_quad_rl_0" />
        <motor name="torque_quad_rl_1"  ctrllimited="true" ctrlrange="-500 500"   joint="joint_quad_rl_1" />
        <motor name="torque_quad_rl_2"  ctrllimited="true" ctrlrange="-500 500"   joint="joint_quad_rl_2" />

        <motor name="torque_arm_0"      ctrllimited="true" ctrlrange="-250 250"     joint="joint_arm_0"     />
        <motor name="torque_arm_1"      ctrllimited="true" ctrlrange="-250 250"     joint="joint_arm_1"     />
        <motor name="torque_arm_2"      ctrllimited="true" ctrlrange="-250 250"     joint="joint_arm_2"     />
        <motor name="torque_arm_3"      ctrllimited="true" ctrlrange="-150 150"     joint="joint_arm_3"     />
        <motor name="torque_arm_4"      ctrllimited="true" ctrlrange="-150 150"     joint="joint_arm_4"     />
        <motor name="torque_arm_5"      ctrllimited="true" ctrlrange="-150 150"     joint="joint_arm_5"     />

    </actuator>

    <asset>
        <mesh name="spot_body"      file="meshes/spot_body.stl"      />
        <mesh name="fl_hip"         file="meshes/fl_hip.stl"         />
        <mesh name="fr_hip"         file="meshes/fr_hip.stl"         />
        <mesh name="hl_hip"         file="meshes/hl_hip.stl"         />
        <mesh name="hr_hip"         file="meshes/hr_hip.stl"         />
        <mesh name="fl_uleg"        file="meshes/fl_uleg.stl"        />
        <mesh name="fr_uleg"        file="meshes/fr_uleg.stl"        />
        <mesh name="hl_uleg"        file="meshes/hl_uleg.stl"        />
        <mesh name="hr_uleg"        file="meshes/hr_uleg.stl"        />
        <mesh name="lleg"           file="meshes/lleg.stl"           />
        <mesh name="arm0_link_0"    file="meshes/arm0_link_sh0.stl"  />
        <mesh name="arm0_link_1"    file="meshes/arm0_link_sh1.stl"  />
        <mesh name="arm0_link_2"    file="meshes/arm0_link_hr0.stl"  />
        <mesh name="arm0_link_3"    file="meshes/arm0_link_el0.stl"  />
        <mesh name="arm0_link_4"    file="meshes/arm0_link_el1.stl"  />
        <mesh name="arm0_link_5"    file="meshes/arm0_link_wr0.stl"  />
        <mesh name="arm0_link_6"    file="meshes/arm0_link_wr1.stl"  />
        <mesh name="arm0_link_fngr" file="meshes/arm0_link_fngr.stl" />
    </asset>

    <worldbody>
        <body name="floating_base" pos="0 0 0">

        <body>
            <joint armature="0" damping="0" limited="false" name="root" axis="1 0 0" stiffness="0" type="slide"/>
            <inertial pos="0 0 0" mass="1.0e-6" diaginertia="1.0e-9 1.0e-9 1.0e-9"/>
        <body>
            <joint armature="0" damping="0" limited="false" name="root_y" axis="0 1 0" stiffness="0" type="slide"/>
            <inertial pos="0 0 0" mass="1.0e-6" diaginertia="1.0e-9 1.0e-9 1.0e-9"/>
        <body>
            <joint armature="0" damping="0" limited="false" name="root_z" axis="0 0 1" stiffness="0" type="slide"/>
            <inertial pos="0 0 0" mass="1.0e-6" diaginertia="1.0e-9 1.0e-9 1.0e-9"/>
        <body>
            <joint armature="0" damping="0" limited="false" name="root_r" axis="1 0 0" stiffness="0" type="hinge"/>
            <inertial pos="0 0 0" mass="1.0e-6" diaginertia="1.0e-9 1.0e-9 1.0e-9"/>
        <body>
            <joint armature="0" damping="0" limited="false" name="root_p" axis="0 1 0" stiffness="0" type="hinge"/>
            <inertial pos="0 0 0" mass="1.0e-6" diaginertia="1.0e-9 1.0e-9 1.0e-9"/>
        <body name="base" pos="0 0 0">
            <inertial pos="0 0 -0.00496172" quat="0 0.707107 0 0.707107" mass="16.7077" diaginertia="0.569454 0.549231 0.0815438" />
            <joint armature="0" damping="0" limited="false" name="root_yw" axis="0 0 1" stiffness="0" type="hinge"/>

            <geom type="mesh" mesh="spot_body" 
                contype="0" conaffinity="0" group="1" 
                rgba="0.2 0.2 0.2 1"
                />

            <body name="link_quad_fl_0" pos="0.29785 0.055 0">

                <inertial pos="-0.0158674 0.00855842 9.03e-06" quat="-0.137996 0.694859 0.131743 0.693377" mass="1.13688" diaginertia="0.00172904 0.00166127 0.00114996" />
                <joint name="joint_quad_fl_0" 
                    pos="0 0 0" axis="1 0 0" 
                    limited="true" range="-0.785398 0.785398"
                    frictionloss="0" damping="0.0"
                    />
                <geom type="mesh" mesh="fl_hip"
                    contype="0" conaffinity="0" group="1" 
                    />
                <geom type="cylinder" size="0.04 0.04" 
                    pos="0 0.055 0" quat="1 1 0 0" 
                    group="0"
                    />
                
                <body name="link_quad_fl_1" pos="0 0.110945 0">
                    <inertial pos="0.00214442 -0.0111018 -0.078812" quat="0.998684 0.0454551 -0.0106253 -0.0212473" mass="2.2562" diaginertia="0.0269394 0.0260254 0.00298666" />
                    <joint name="joint_quad_fl_1" 
                        pos="0 0 0" axis="0 1 0" 
                        limited="true" range="-0.898845 2.29511"
                        frictionloss="0" damping="0.0"
                        />
                    <geom type="mesh" mesh="fl_uleg"
                        contype="0" conaffinity="0" group="1" 
                        />
                    <body name="link_quad_fl_2" pos="0.025 0 -0.3205">
                        <inertial pos="0.0059736 0 -0.174664" quat="0.707099 -0.00339701 -0.00339701 0.707099" mass="0.33" diaginertia="0.00709946 0.00701419 0.000144656" />
                        <joint name="joint_quad_fl_2" 
                            pos="0 0 0" axis="0 1 0" 
                            limited="true" range="-2.7929 -0.2471" 
                            frictionloss="0" damping="0.0"
                            />
                        <geom type="mesh" mesh="lleg"
                            contype="0" conaffinity="0" group="1" 
                            />
                        <body name="frame_fl_foot" pos="0 0 -0.33">
                            <inertial pos="0 0 0" mass="1.0e2" diaginertia="0.0001 0.0001 0.0001" />
                            <geom type="sphere" size="0.05" 
                                rgba="0 0 0 0"
                                friction="1 1 1"
                                group="0" contype="1" conaffinity="1"
                                />
                        </body>
                    </body>
                </body>
            </body>
            <body name="link_quad_fr_0" pos="0.29785 -0.055 0">
                <inertial pos="-0.0158674 -0.00855842 9.03e-06" quat="0.137996 0.694859 -0.131743 0.693377" mass="1.13688" diaginertia="0.00172904 0.00166127 0.00114996" />
                <joint name="joint_quad_fr_0" 
                    pos="0 0 0" axis="1 0 0" 
                    limited="true" range="-0.785398 0.785398" 
                    frictionloss="0" damping="0.0"
                    />
                <geom type="mesh" mesh="fr_hip"
                    contype="0" conaffinity="0" group="1" 
                    />
                <geom type="cylinder" size="0.04 0.04" 
                    pos="0 -0.055 0" quat="1 1 0 0" 
                    group="0"
                    />
                <body name="link_quad_fr_1" pos="0 -0.110945 0">
                    <inertial pos="0.00214442 0.0111018 -0.078812" quat="0.998684 -0.0454551 -0.0106253 0.0212473" mass="2.2562" diaginertia="0.0269394 0.0260254 0.00298666" />
                    <joint name="joint_quad_fr_1" 
                        pos="0 0 0" axis="0 1 0" 
                        limited="true" range="-0.898845 2.29511" 
                        frictionloss="0" damping="0.0"
                        />
                    <geom type="mesh" mesh="fr_uleg"
                        contype="0" conaffinity="1" group="1" 
                        />
                    <body name="link_quad_fr_2" pos="0.025 0 -0.3205">
                        <inertial pos="0.0059736 0 -0.174664" quat="0.707099 -0.00339701 -0.00339701 0.707099" mass="0.33" diaginertia="0.00709946 0.00701419 0.000144656" />
                        <joint name="joint_quad_fr_2" 
                            pos="0 0 0" axis="0 1 0" 
                            limited="true" range="-2.7929 -0.2471"
                            frictionloss="0" damping="0.0"
                            />
                        <geom type="mesh" mesh="lleg"
                            contype="0" conaffinity="0" group="1" 
                            />
                        <body name="frame_fr_foot" pos="0 0 -0.33">
                            <inertial pos="0 0 0" mass="1.0e2" diaginertia="0.0001 0.0001 0.0001" />
                            <geom type="sphere" size="0.05" 
                                rgba="0 0 0 0"
                                friction="1 1 1"
                                group="0" contype="1" conaffinity="1"
                                />
                        </body>
                    </body>
                </body>
            </body>
            <body name="link_quad_rl_0" pos="-0.29785 0.055 0">
                <inertial pos="0.0158674 0.00855842 9.03e-06" quat="0.131743 0.693377 -0.137996 0.694859" mass="1.13688" diaginertia="0.00172904 0.00166127 0.00114996" />
                <joint name="joint_quad_rl_0" 
                    pos="0 0 0" axis="1 0 0" 
                    limited="true" range="-0.785398 0.785398" 
                    frictionloss="0" damping="0.0"
                    />
                <geom type="mesh" mesh="hl_hip"
                    contype="0" conaffinity="0" group="1" 
                    />
                <geom type="cylinder" size="0.04 0.04" 
                    pos="0 0.055 0" quat="1 1 0 0" 
                    group="0"
                    />
                <body name="link_quad_rl_1" pos="0 0.110945 0">
                    <inertial pos="0.00214442 -0.0111018 -0.078812" quat="0.998684 0.0454551 -0.0106253 -0.0212473" mass="2.2562" diaginertia="0.0269394 0.0260254 0.00298666" />
                    <joint name="joint_quad_rl_1" 
                        pos="0 0 0" axis="0 1 0" 
                        limited="true" range="-0.898845 2.29511" 
                        frictionloss="0" damping="0.0"
                        />
                    <geom type="mesh" mesh="hl_uleg"
                        contype="0" conaffinity="1" group="1" 
                        />
                    <body name="link_quad_rl_2" pos="0.025 0 -0.3205">
                        <inertial pos="0.0059736 0 -0.174664" quat="0.707099 -0.00339701 -0.00339701 0.707099" mass="0.33" diaginertia="0.00709946 0.00701419 0.000144656" />
                        <joint name="joint_quad_rl_2" 
                            pos="0 0 0" axis="0 1 0" 
                            limited="true" range="-2.7929 -0.2471" 
                            frictionloss="0" damping="0.0"
                            />
                        <geom type="mesh" mesh="lleg"
                            contype="0" conaffinity="0" group="1" 
                            />
                        <body name="frame_rl_foot" pos="0 0 -0.33">
                            <inertial pos="0 0 0" mass="1.0e2" diaginertia="0.0001 0.0001 0.0001" />
                            <geom type="sphere" size="0.05" 
                                rgba="0 0 0 0"
                                friction="1 1 1"
                                group="0" contype="1" conaffinity="1"
                                />
                        </body>
                    </body>
                </body>
            </body>
            <body name="link_quad_rr_0" pos="-0.29785 -0.055 0">
                <inertial pos="0.0158674 -0.00855842 9.03e-06" quat="-0.131743 0.693377 0.137996 0.694859" mass="1.13688" diaginertia="0.00172904 0.00166127 0.00114996" />
                <joint name="joint_quad_rr_0" 
                    pos="0 0 0" axis="1 0 0" 
                    limited="true" range="-0.785398 0.785398" 
                    frictionloss="0" damping="0.0"
                    />
                <geom type="mesh" mesh="hr_hip"
                    contype="0" conaffinity="0" group="1" 
                    />
                <geom type="cylinder" size="0.04 0.04" 
                    pos="0 -0.055 0" quat="1 1 0 0" 
                    group="0"
                    />                
                <body name="link_quad_rr_1" pos="0 -0.110945 0">
                    <inertial pos="0.00214442 0.0111018 -0.078812" quat="0.998684 -0.0454551 -0.0106253 0.0212473" mass="2.2562" diaginertia="0.0269394 0.0260254 0.00298666" />
                    <joint name="joint_quad_rr_1" 
                        pos="0 0 0" axis="0 1 0" 
                        limited="true" range="-0.898845 2.29511"
                        frictionloss="0" damping="0.0"
                        />
                    <geom type="mesh" mesh="hr_uleg"
                        contype="0" conaffinity="1" group="1" 
                        />
                    <body name="link_quad_rr_2" pos="0.025 0 -0.3205">
                        <inertial pos="0.0059736 0 -0.174664" quat="0.707099 -0.00339701 -0.00339701 0.707099" mass="0.33" diaginertia="0.00709946 0.00701419 0.000144656" />
                        <joint name="joint_quad_rr_2" 
                            pos="0 0 0" axis="0 1 0" 
                            limited="true" range="-2.7929 -0.2471" 
                            frictionloss="0" damping="0.0"
                            />
                        <geom type="mesh" mesh="lleg"
                            contype="0" conaffinity="0" group="1" 
                            />
                        <body name="frame_rr_foot" pos="0 0 -0.33">
                            <inertial pos="0 0 0" mass="1.0e2" diaginertia="0.0001 0.0001 0.0001" />
                            <geom type="sphere" size="0.05" 
                                rgba="0 0 0 0"
                                friction="1 1 1"
                                group="0" contype="1" conaffinity="1"
                                />
                        </body>
                    </body>
                </body>
            </body>
            
            <body name="link_arm_0" pos="0.292 0 0.188">
                <inertial pos="-0.008399 0.000272 -0.024603" quat="0.710827 0.700855 0.0423863 -0.0416066" mass="1.9047" diaginertia="0.00891905 0.00728042 0.00492153" />
                <joint name="joint_arm_0"
                    pos="0 0 0" axis="0 0 1" 
                    type="hinge" limited="true" range="-2.61799 3.14159" 
                    frictionloss="0" damping="0.0"
                    />
                <geom type="mesh" contype="0" conaffinity="0" group="1" mesh="arm0_link_0" />
                <!-- <geom type="mesh" contype="1" conaffinity="1" group="1" mesh="arm0_link_0" /> -->

                <body name="link_arm_1" pos="0 0 0">
                    <inertial pos="0.0808491 -0.00167243 0.00045644" quat="-0.00467017 0.708456 0.00702831 0.705705" mass="1.85702" diaginertia="0.0281997 0.0270454 0.00260818" />
                    <joint name="joint_arm_1" 
                        pos="0 0 0" axis="0 1 0" 
                        type="hinge" limited="true" range="-3.14159 0.523599" 
                        frictionloss="0" damping="0.0"
                        />
                    <geom type="mesh" contype="0" conaffinity="0" group="1" mesh="arm0_link_1" />
                    <geom type="mesh" contype="0" conaffinity="0" group="1" mesh="arm0_link_2" />
                    <!-- <geom type="mesh" contype="1" conaffinity="1" group="1" mesh="arm0_link_1" /> -->
                    <!-- <geom type="mesh" contype="1" conaffinity="1" group="1" mesh="arm0_link_2" /> -->

                    <body name="link_arm_2" pos="0.3385 0 0">
                        <inertial pos="0.0447662 -0.0027113 0.0499136" quat="0.0923782 0.888458 0.19384 0.40563" mass="0.94832" diaginertia="0.00286401 0.00265579 0.000960161" />
                        <joint name="joint_arm_2" 
                            pos="0 0 0" axis="0 1 0" 
                            type="hinge" limited="true" range="0 3.14159" 
                            frictionloss="0" damping="0.0"
                            />
                        <geom type="mesh" contype="0" conaffinity="0" group="1" mesh="arm0_link_3" />
                        <!-- <geom type="mesh" contype="1" conaffinity="1" group="1" mesh="arm0_link_3" /> -->

                        <body name="link_arm_3" pos="0.4033 0 0.075">
                            <inertial pos="-0.168671 -0.0161612 1.149e-05" quat="0.488034 0.425158 0.565043 0.511654" mass="1.01755" diaginertia="0.0169253 0.0168986 0.000746021" />
                            <joint name="joint_arm_3" 
                                pos="0 0 0" axis="1 0 0" 
                                type="hinge" limited="true" range="-2.79253 2.79253" 
                                frictionloss="0" damping="0.0"
                                />
                            <geom type="mesh" contype="0" conaffinity="0" group="1" mesh="arm0_link_4" />
                            <!-- <geom type="mesh" contype="1" conaffinity="1" group="1" mesh="arm0_link_4" /> -->

                            <body name="link_arm_4" pos="0 0 0">
                                <inertial pos="0.00952465 -0.0114441 1.86e-06" quat="0.308237 0.652328 -0.273781 0.636005" mass="0.582637" diaginertia="0.000536182 0.000528639 0.000388399" />
                                <joint name="joint_arm_4" 
                                    pos="0 0 0" axis="0 1 0" 
                                    type="hinge" limited="true" range="-1.8326 1.8326" 
                                    frictionloss="0" damping="0.0"
                                    />
                                <geom type="mesh" contype="0" conaffinity="0" group="1" mesh="arm0_link_5" />
                                <!-- <geom type="mesh" contype="1" conaffinity="1" group="1" mesh="arm0_link_5" /> -->

                                <body name="link_arm_5" pos="0 0 0">
                                    <inertial pos="0.0975128 9.265e-05 -0.0112052" quat="0.592778 0.385047 0.386229 0.592605" mass="0.933353" diaginertia="0.00197018 0.00182151 0.00082476" />
                                    <joint name="joint_arm_5" 
                                        pos="0 0 0" axis="1 0 0" 
                                        type="hinge" limited="true" range="-2.87989 2.87979" 
                                        frictionloss="0" damping="0.0"
                                        />
                                    <body name="eef_point" pos="0.06 0.0 0.0">
                                    <body name="gripper_mount" pos="0.0 0.0 0.0" quat="0.5 0.5 0.5 0.5">
                                        <camera mode="fixed" name="stereo_l_right_hand" pos="0.05 0.1 0.0" quat="0 1 0 0" fovy="120"/>
                                        <camera mode="fixed" name="stereo_r_right_hand" pos="-0.05 0.1 0.0" quat="0 1 0 0" fovy="120"/>
                                    </body>
                                    </body>
                                    
                                    <body name="tool_point" pos="0.2 0.0 -0.03">
                                        <body name="tool_mount" pos="0.0 0.0 0.0" quat="0.5 0.5 0.5 0.5"/>
                                    </body>

                                    <geom type="mesh" contype="1" conaffinity="1" group="1" mesh="arm0_link_6" />

                                    <body name="link_gripper_0" pos="0.11745 0 0.01482">
                                        <inertial pos="0.0356518 0.000672 -0.0122752" quat="0.00481109 0.567709 0.0124565 0.823121" mass="0.223833" diaginertia="0.000648792 0.000484516 0.000194933" />
                                        <!-- <joint name="joint_gripper_0" 
                                            pos="0 0 0" axis="0 1 0" 
                                            type="hinge" limited="true" range="-1.5708 0" 
                                            frictionloss="0" damping="0.0"
                                            /> -->
                                        <geom type="mesh" contype="1" conaffinity="1" group="1" mesh="arm0_link_fngr" />
                                    </body>
                                </body>
                            </body>
                        </body>
                    </body>
                </body>
            </body>
        </body>
    </body>
    </body>
    </body>
    </body>
    </body>
    </body>
    </worldbody>

</mujoco>