<?xml version="1.0" encoding="utf-8"?>

<mujoco model="shelf">
    <asset>
        <texture file="../textures/steel-brushed.png" type="cube" name="steel" />
        <texture file="../textures/light-wood.png" type="cube" name="light-wood" />
        <texture file="../textures/dark-wood.png" type="cube" name="dark-wood" />
        <material name="MatSteel" texture="steel" specular="1" shininess="0.3" rgba="0.9 0.9 0.9 1" />
        <material name="MatLightWood" texture="light-wood" texrepeat="3 3" specular="0.4" shininess="0.1" />
        <material name="MatDarkWood" texture="dark-wood" texrepeat="3 3" specular="0.4" shininess="0.1" />
    </asset>

    <worldbody>
        <body>
            <body name="object" pos="0 0 0.25">
                <inertial pos="0 0 0" mass="5.0" diaginertia="0.03417 0.025633 0.028333"
                    />

                <!-- Base -->
                <geom name="geom_base"
                    pos="0 0 -0.215" size="0.25 0.15 0.035" type="box" 
                    group="0" friction="1 1 1"
                    rgba="0 0 0 0"
                    />
                <geom name="geom_base_visual"
                    pos="0 0 -0.215" size="0.25 0.15 0.035" type="box" 
                    material="MatLightWood"
                    group="1" contype="0" conaffinity="0"
                    />

                <!-- Top -->
                <geom name="geom_top"
                    pos="0 0 0.19" size="0.25 0.15 0.01" type="box" 
                    group="0" friction="1 1 1"
                    rgba="0 0 0 0"
                    />
                <geom name="geom_top_visual"
                    pos="0 0 0.19" size="0.25 0.15 0.01" type="box" 
                    material="MatLightWood"
                    group="1" contype="0" conaffinity="0"
                    />

                <!-- Back -->
                <geom name="geom_back"
                    pos="0 -0.14 0" size="0.23 0.01 0.18" type="box"
                    group="0" friction="1 1 1"
                    rgba="0 0 0 0"
                    />
                <geom name="geom_back_visual"
                    pos="0 -0.14 0" size="0.23 0.01 0.18" type="box"
                    material="MatLightWood"
                    group="1" contype="0" conaffinity="0"
                    />

                <!-- Sides -->
                <geom name="geom_left_side"
                    pos="-0.24 0 0" size="0.01 0.15 0.18" type="box"
                    group="0" friction="1 1 1"
                    rgba="0 0 0 0"
                    />
                <geom name="geom_left_side_visual"
                    pos="-0.24 0 0" size="0.01 0.15 0.18" type="box"
                    material="MatLightWood"
                    group="1" contype="0" conaffinity="0"
                    />

                <geom name="geom_right_side"
                    pos="0.24 0 0" size="0.01 0.15 0.18" type="box" 
                    group="0" friction="1 1 1"
                    rgba="0 0 0 0"
                    />
                <geom name="geom_right_side_visual"
                    pos="0.24 0 0" size="0.01 0.15 0.18" type="box" 
                    material="MatLightWood"
                    group="1" contype="0" conaffinity="0"
                    />

                <!-- Left door -->
                <body name="left_door" pos="0.125 0.16 0.0">
                    <joint name="left_joint"
                        type="hinge" pos = "0.125 -0.01 0" axis="0 0 -1" limited="true" range="0 3.1416" 
                        damping="0.05" stiffness="1.0" frictionloss="0.3" springref="1.8" 
                        ref="0"
                        />
                    <inertial pos="0 0 0" mass="0.1" diaginertia="0.0013467 0.001854 0.0005342"
                        />
                    <!-- <geom 
                        type="cylinder" size="0.01 0.2" 
                        pos="0.125 -0.01 0" 
                        material="MatDarkWood"
                        group="0"
                        /> -->
                    <geom name="geom_left_door"
                        size="0.125 0.01 0.2" type="box"
                        pos="0 0 0"
                        group="0" friction="1 1 1"
                        rgba="0 0 0 0"
                        />
                    <geom name="geom_left_door_visual"
                        size="0.125 0.01 0.2" type="box"
                        pos="0 0 0"
                        group="1" contype="0" conaffinity="0"
                        material="MatDarkWood"
                        />

                    <body name="left_handle" pos="-0.09 0.01 0" quat="0 0 0.707107 0.707107">
                        <geom name="geom_left_top_root1"
                            fromto="0  0.04 0  0  0.04 0.04" size="0.005" type="box" 
                            group="0" friction="1 1 1"
                            rgba="0 0 0 0"
                            />
                        <geom name="geom_left_top_root2"
                            fromto="0 -0.04 0    0 -0.04 0.04" size="0.005" type="box" 
                            group="0" friction="1 1 1"
                            rgba="0 0 0 0"
                            />
                        <geom name="geom_left_top_handle"
                            fromto="0 -0.04 0.04 0  0.04 0.04" size="0.013" type="box" 
                            group="0" friction="1 1 1"
                            rgba="0 0 0 0"
                            />
                        <geom name="geom_left_top_root1_visual"
                            fromto="0  0.04 0  0  0.04 0.04" size="0.005" type="capsule" 
                            group="1" contype="0" conaffinity="0"
                            material="MatSteel"
                            />
                        <geom name="geom_left_top_root2_visual"
                            fromto="0 -0.04 0    0 -0.04 0.04" size="0.005" type="capsule" 
                            group="1" contype="0" conaffinity="0"
                            material="MatSteel"
                            />
                        <geom name="geom_left_top_handle_visual"
                            fromto="0 -0.04 0.04 0  0.04 0.04" size="0.013" type="capsule" 
                            group="1" contype="0" conaffinity="0"
                            material="MatLightWood"
                            />
                        <site name="left_handle" pos="0.125 -0.10 0" size="0.02" rgba="0 0 1 0" />
                    </body>
                </body>

                <!-- Right door -->
                <body name="right_door" pos="-0.125 0.16 0.0">
                    <joint name="right_joint"
                        type="hinge" pos = "-0.125 -0.01 0" axis="0 0 1" limited="true" range="0 3.1416" 
                        damping="0.05" stiffness="1.0" frictionloss="0.3" springref="1.8" 
                        ref="0"
                        />
                    <inertial pos="0 0 0" mass="0.1" diaginertia="0.0003467 0.0024167 0.0020967"
                        />
                    <!-- <geom 
                        type="cylinder" size="0.01 0.2" 
                        pos="-0.125 -0.01 0" 
                        material="MatDarkWood"
                        group="0"
                        /> -->
                    <geom name="geom_right_door"
                        size="0.125 0.01 0.2" type="box"
                        pos="0 0 0"
                        group="0" friction="1 1 1"
                        rgba="0 0 0 0"
                        />
                    <geom name="geom_right_door_visual"
                        size="0.125 0.01 0.2" type="box"
                        pos="0 0 0"
                        group="1" contype="0" conaffinity="0"
                        material="MatDarkWood"
                        />

                    <body name="right_handle" pos="0.09 0.01 0" quat="0 0 0.707107 0.707107">
                        <geom name="geom_right_top_root1"
                            fromto="0  0.04 0  0  0.04 0.04" size="0.005" type="box" 
                            group="0" friction="1 1 1"
                            rgba="0 0 0 0"
                            />
                        <geom name="geom_right_top_root2"
                            fromto="0 -0.04 0    0 -0.04 0.04" size="0.005" type="box" 
                            group="0" friction="1 1 1"
                            rgba="0 0 0 0"
                            />
                        <geom name="geom_right_top_handle"
                            fromto="0 -0.04 0.04 0  0.04 0.04" size="0.013" type="box" 
                            group="0" friction="1 1 1"
                            rgba="0 0 0 0"
                            />
                        <geom name="geom_right_top_root1_visual"
                            fromto="0  0.04 0  0  0.04 0.04" size="0.005" type="capsule" 
                            group="1" contype="0" conaffinity="0"
                            material="MatSteel"
                            />
                        <geom name="geom_right_top_root2_visual"
                            fromto="0 -0.04 0    0 -0.04 0.04" size="0.005" type="capsule" 
                            group="1" contype="0" conaffinity="0"
                            material="MatSteel"
                            />
                        <geom name="geom_right_top_handle_visual"
                            fromto="0 -0.04 0.04 0  0.04 0.04" size="0.013" type="capsule" 
                            group="1" contype="0" conaffinity="0"
                            material="MatLightWood"
                            />
                        <site name="right_handle" pos="0.125 -0.10 0" size="0.02" rgba="0 0 1 0" />
                    </body>
                </body>
            </body>
            <site name="bottom_site" pos="0 0 -0.0207" rgba="0 0 0 0" size="0.005"/>
            <site name="top_site" pos="0 0 0.007" rgba="0 0 0 0" size="0.005"/>
            <site name="horizontal_radius_site" pos="0 0 0" rgba="0 0 0 0" size="0.003"/>
        </body>

    </worldbody>
</mujoco>
